Workbook

Sheet Valuation
A1: Murata (6981.T): house valuation
A2: Method: EV / 5-yr-mean EBITDA, own band p25/median/p75 (no regime credit); P/B timing check. Price 2-Oct-2026.
A4: Line | B4: Bear | C4: Base | D4: Bull | E4: Prob-weighted
A5: Probability | B5: =Scenarios!B28 | C5: =Scenarios!B55 | D5: =Scenarios!B82
A6: Exit multiple (x) | B6: =Scenarios!B20 | C6: =Scenarios!B47 | D6: =Scenarios!B74
A7: 5-yr mean EBITDA (JPY mn) | B7: =Scenarios!B19 | C7: =Scenarios!B46 | D7: =Scenarios!B73 | E7: =SUMPRODUCT(B5:D5,B7:D7)
A8: FY3/30 EBITDA (JPY mn) | B8: =Scenarios!E12 | C8: =Scenarios!E39 | D8: =Scenarios!E66 | E8: =SUMPRODUCT(B5:D5,B8:D8)
A9: Net cash Mar-2030 (JPY mn) | B9: =Scenarios!E17 | C9: =Scenarios!E44 | D9: =Scenarios!E71 | E9: =SUMPRODUCT(B5:D5,B9:D9)
A10: Value per share at exit | B10: =Scenarios!B23 | C10: =Scenarios!B50 | D10: =Scenarios!B77 | E10: =SUMPRODUCT(B5:D5,B10:D10)
A11: PV per share at CoE | B11: =Scenarios!B26 | C11: =Scenarios!B53 | D11: =Scenarios!B80 | E11: =SUMPRODUCT(B5:D5,B11:D11)
A12: IRR from today | B12: =Scenarios!B25 | C12: =Scenarios!B52 | D12: =Scenarios!B79 | E12: =((E10+SUM(Inputs!B24:E24))/Inputs!$B$5)^(1/Inputs!$B$16)-1
A13: Entry for 20% IRR | B13: =Scenarios!B27 | C13: =Scenarios!B54 | D13: =Scenarios!B81 | E13: =SUMPRODUCT(B5:D5,B13:D13)
A16: Share price | B16: =Inputs!$B$5
A17: PW PV vs price | B17: =E11/B16-1
A18: EV / 5y-mean EBITDA today | B18: =Band!F8
A19: Own-band median | B19: =Band!F6
A20: Reverse: exit multiple the price needs for a 0% IRR (Base) | B20: =(Inputs!$B$5*Inputs!$B$6-Scenarios!E44)/Scenarios!B46
A21: Reverse: exit multiple the price needs for a 20% IRR (Base) | B21: =(Inputs!$B$5*(1+Inputs!$B$17)^Inputs!$B$16*Inputs!$B$6-Scenarios!E44)/Scenarios!B46
A22: P/B today vs own median (timing check) | B22: =Band!G9
A24: Verdict | B24: =IF(B16>E13,"Above the 20%-IRR entry: wait / avoid on the house method",IF(B16>E11,"Between entry and PW value: hold","Below PW value: buy"))

Sheet Inputs
A1: Murata Manufacturing (6981.T): inputs
A2: Yellow = input. JPY mn unless stated. Price 2 Oct 2026 close. Sources on the Sources sheet.
A4: Item | B4: Value | C4: Note
A5: Share price (JPY) | B5: 8467 | C5: Yahoo 2-Oct-2026
A6: Shares outstanding ex-treasury (mn) | B6: 1820.292 | C6: Fact book 2026, FY3/26 split-adjusted
A7: Net cash FY3/26 | B7: 650441 | C7: Cash 653.7bn less debt 3.3bn, fact book 2026
A8: FY3/27 operating profit guide | B8: 430000 | C8: Murata 31-Jul-2026 revision
A9: FY3/27 D&A guide | B9: 178000 | C9: April guide, not revised
A10: FY3/27 capacitor revenue guide | B10: 1157500 | C10: 31-Jul-2026 revision
A11: FY3/27 total revenue guide | B11: 2110000 | C11: 31-Jul-2026 revision
A12: Other-business EBITDA margin | B12: 0.13 | C12: Derived: FY3/26 EBITDA less capacitors at ~38% [E]
A13: Drop-through of price on capacitor EBITDA | B13: 0.9 | C13: Assumption: price changes fall almost fully to EBITDA [A]
A14: Tax + minorities on (EBITDA - D&A) | B14: 0.23 | C14: FY3/26 net income / OP ≈ 0.83, less finance income [E]
A15: Cost of equity (CAPM) | B15: 0.08 | C15: JGB 10y ~1.6% + 1.0 beta x 6.5% ERP [A]
A16: Years to exit (to Mar-2030) | B16: 3.5 | C16: Oct-2026 to end FY3/30
A17: Target IRR for entry | B17: 0.2 | C17: House rule
A18: EBITDA FY3/26 (actual) | B18: =History!P7 | C18: Op income + D&A
A20: Forward schedule (all scenarios)
A21: Item | B21: FY3/27 | C21: FY3/28 | D21: FY3/29 | E21: FY3/30 | F21: Note
A22: D&A | B22: 178000 | C22: 190000 | D22: 200000 | E22: 205000 | F22: Rises with the new Izumo building [A]
A23: Capex | B23: 255000 | C23: 240000 | D23: 230000 | E23: 220000 | F23: FY3/27 guide 255bn; then tapering [A]
A24: DPS (JPY) | B24: 70 | C24: 75 | D24: 80 | E24: 85 | F24: FY3/27 guide 70; +5/yr [A]
A26: Scenario drivers (FY3/28, FY3/29, FY3/30)
A27: Driver | B27: Bear | C27: Base | D27: Bull | E27: Note
A28: Probability | B28: 0.25 | C28: 0.5 | D28: 0.25 | E28: House convention 25/50/25
A29: Capacitor volume FY3/28 | B29: 0.05 | C29: 0.15 | D29: 0.2 | E29: AI-server units +30%/yr (Murata) vs consumer flat
A30: Capacitor volume FY3/29 | B30: -0.08 | C30: 0.08 | D30: 0.12 | E30: Bear = 2019-style destock
A31: Capacitor volume FY3/30 | B31: 0.02 | C31: -0.02 | D31: 0.05
A32: Capacitor price FY3/28 | B32: -0.03 | C32: 0.03 | D32: 0.1 | E32: Bull = Murata joins SEMCO/Yageo hikes
A33: Capacitor price FY3/29 | B33: -0.1 | C33: 0.01 | D33: 0.03 | E33: Bear = 2019 ASP -15%/qtr at Yageo
A34: Capacitor price FY3/30 | B34: -0.03 | C34: -0.05 | D34: -0.02 | E34: Normal annual price erosion returns
A35: Other revenue growth p.a. | B35: 0.02 | C35: 0.03 | D35: 0.04 | E35: RF modules, inductors, batteries
A36: Exit EV / 5-yr-mean EBITDA (x) | B36: =Band!$F$5 | C36: =Band!$F$6 | D36: =Band!$F$7 | E36: Own band p25 / median / p75, May-2016 to now

Sheet History
A1: Murata: 15 years of history (FYE March, JPY mn)
A2: Murata fact books 2022/2024/2026. US GAAP to FY3/23, IFRS from FY3/24 (FY3/23 shown IFRS-restated where available).
A3: Metric | B3: FY3/2012 | C3: FY3/2013 | D3: FY3/2014 | E3: FY3/2015 | F3: FY3/2016 | G3: FY3/2017 | H3: FY3/2018 | I3: FY3/2019 | J3: FY3/2020 | K3: FY3/2021 | L3: FY3/2022 | M3: FY3/2023 | N3: FY3/2024 | O3: FY3/2025 | P3: FY3/2026
A4: Revenue | B4: 584662 | C4: 681021 | D4: 846716 | E4: 1043542 | F4: 1210841 | G4: 1135524 | H4: 1371842 | I4: 1575026 | J4: 1534045 | K4: 1630193 | L4: 1812521 | M4: 1686796 | N4: 1640158 | O4: 1743352 | P4: 1830856
A5: Operating income | B5: 44973 | C5: 58636 | D5: 125891 | E5: 214535 | F5: 275406 | G5: 201215 | H5: 163254 | I5: 266807 | J5: 253247 | K5: 313240 | L5: 424060 | M5: 297887 | N5: 215447 | O5: 279702 | P5: 281835
A6: D&A | B6: 61008 | C6: 72323 | D6: 76884 | E6: 84935 | F6: 99105 | G6: 113523 | H6: 141625 | I6: 124419 | J6: 140267 | K6: 143074 | L6: 155583 | M6: 169618 | N6: 175873 | O6: 173335 | P6: 178212
A7: EBITDA | B7: =B5+B6 | C7: =C5+C6 | D7: =D5+D6 | E7: =E5+E6 | F7: =F5+F6 | G7: =G5+G6 | H7: =H5+H6 | I7: =I5+I6 | ... P7: =P5+P6
A8: EBITDA margin | B8: =B7/B4 | C8: =C7/C4 | D8: =D7/D4 | E8: =E7/E4 | F8: =F7/F4 | G8: =G7/G4 | H8: =H7/H4 | I8: =I7/I4 | ... P8: =P7/P4
A9: 5-yr mean EBITDA | F9: =AVERAGE(B7:F7) | G9: =AVERAGE(C7:G7) | H9: =AVERAGE(D7:H7) | I9: =AVERAGE(E7:I7) | J9: =AVERAGE(F7:J7) | K9: =AVERAGE(G7:K7) | L9: =AVERAGE(H7:L7) | M9: =AVERAGE(I7:M7) | ... P9: =AVERAGE(L7:P7)
A10: Capacitor revenue | B10: 208386 | C10: 228719 | D10: 276574 | E10: 334272 | F10: 367319 | G10: 369488 | H10: 449801 | I10: 574230 | J10: 559438 | K10: 626546 | L10: 788539 | M10: 738841 | N10: 753520 | O10: 831845 | P10: 936418
A11: Capacitor share of revenue | B11: =B10/B4 | C11: =C10/C4 | D11: =D10/D4 | E11: =E10/E4 | F11: =F10/F4 | G11: =G10/G4 | H11: =H10/H4 | I11: =I10/I4 | ... P11: =P10/P4
A12: Net income | B12: 30807 | C12: 42386 | D12: 93191 | E12: 167711 | F12: 203776 | G12: 156060 | H12: 146086 | I12: 206930 | J12: 183012 | K12: 237057 | L12: 314124 | M12: 243946 | N12: 180838 | O12: 233818 | P12: 233920
A13: Capex | B13: 68445 | C13: 77662 | D13: 68197 | E13: 101184 | F13: 172540 | G13: 158579 | H13: 306608 | I13: 291581 | J13: 281599 | K13: 196660 | L13: 152786 | M13: 207985 | N13: 219531 | O13: 180471 | P13: 247778
A14: Cash | B14: 65302 | C14: 90068 | D14: 118884 | E14: 212936 | F14: 212570 | G14: 239184 | H14: 187910 | I14: 217805 | J14: 302320 | K14: 407699 | L14: 512072 | M14: 469406 | N14: 622007 | O14: 625148 | P14: 653701
A15: Interest-bearing debt | B15: 37196 | C15: 55605 | D15: 57129 | E15: 25868 | F15: 9747 | G15: 46663 | H15: 14487 | I15: 123614 | J15: 201474 | K15: 150757 | L15: 111078 | M15: 111998 | N15: 52836 | O15: 2437 | P15: 3260
A16: Net cash | B16: =B14-B15 | C16: =C14-C15 | D16: =D14-D15 | E16: =E14-E15 | F16: =F14-F15 | G16: =G14-G15 | H16: =H14-H15 | I16: =I14-I15 | ... P16: =P14-P15
A17: Shares ex-treasury (mn) | B17: 1899.6956 | C17: 1899.6756 | D17: 1905.3695 | E17: 1905.3443 | F17: 1905.3325 | G17: 1914.6446 | H17: 1919.2595 | I17: 1919.3101 | J17: 1919.3893 | K17: 1919.4464 | L17: 1919.4952 | M17: 1889.1707 | N17: 1889.2334 | O17: 1862.361 | P17: 1820.2922
A18: DPS (JPY, split-adj) | B18: 11.11 | C18: 11.11 | D18: 14.44 | E18: 20 | F18: 23.33 | G18: 24.44 | H18: 28.89 | I18: 31.11 | J18: 32.33 | K18: 38.33 | L18: 43.33 | M18: 50 | N18: 52 | O18: 57 | P18: 65
A19: Equity (parent) | B19: 808542 | C19: 860963 | D19: 955760 | E19: 1123090 | F19: 1229159 | G19: 1354819 | H19: 1456600 | I19: 1603976 | J19: 1694104 | K19: 1920805 | L19: 2263596 | M19: 2402511 | N19: 2556147 | O19: 2580805 | P19: 2718743

Sheet Band
A1: Own valuation band: EV / 5-yr-mean EBITDA
A2: Monthly close x shares ex-treasury less net cash of the latest reported FY, over the trailing 5-FY mean EBITDA. P/B shown as the timing check.
A4: Month | B4: EV / 5y-mean EBITDA | C4: P/B | E4: Statistic | F4: EV/5y EBITDA | G4: P/B
A5: 2016-05 | B5: 9.91 | C5: 1.96 | E5: p25 (Bear exit) | F5: =PERCENTILE(B5:B130,0.25) | G5: =PERCENTILE(C5:C130,0.25)
A6: 2016-06 | B6: 11.28 | C6: 2.21 | E6: Median (Base exit) | F6: =MEDIAN(B5:B130) | G6: =MEDIAN(C5:C130)
A7: 2016-07 | B7: 12.31 | C7: 2.39 | E7: p75 (Bull exit) | F7: =PERCENTILE(B5:B130,0.75) | G7: =PERCENTILE(C5:C130,0.75)
A8: 2016-08 | B8: 11.47 | C8: 2.24 | E8: Today | F8: =B130 | G8: =C130
A9: 2016-09 | B9: 13.03 | C9: 2.53 | E9: Today vs median | F9: =B130/MEDIAN(B5:B130)-1 | G9: =C130/MEDIAN(C5:C130)-1
A10: 2016-10 | B10: 13.75 | C10: 2.66
A11: 2016-11 | B11: 13.96 | C11: 2.7 | E11: Band excludes nothing: the 2026 spike is inside the sample. Pre-2026 the median is 11.5x.
A12: 2016-12 | B12: 13.59 | C12: 2.63
A13: 2017-01 | B13: 14.44 | C13: 2.78
A14: 2017-02 | B14: 14.14 | C14: 2.73
A15: 2017-03 | B15: 13.29 | C15: 2.57
A16: 2017-04 | B16: 13.68 | C16: 2.64
A17: 2017-05 | B17: 13 | C17: 2.68
A18: 2017-06 | B18: 13.09 | C18: 2.7
A19: 2017-07 | B19: 12.82 | C19: 2.64
A20: 2017-08 | B20: 12.58 | C20: 2.6
A21: 2017-09 | B21: 13.5 | C21: 2.78
A22: 2017-10 | B22: 11.47 | C22: 2.38
A23: 2017-11 | B23: 11.43 | C23: 2.37
... A130: 2026-10 | B130: 31.39 | C130: 5.67

Sheet Scenarios
A1: Scenarios to FY3/2030 and probability-weighted value
A2: Capacitor EBITDA(t) = capacitor EBITDA(t-1) x (1+volume) + price-driven revenue x drop-through. Exit at Mar-2030 on the own band.
A4: Bear case
A5: Line | B5: FY3/27 | C5: FY3/28 | D5: FY3/29 | E5: FY3/30
A6: Capacitor revenue | B6: =Inputs!$B$10 | C6: =B6*(1+Inputs!$B$29)*(1+Inputs!$B$32) | D6: =C6*(1+Inputs!$B$30)*(1+Inputs!$B$33) | E6: =D6*(1+Inputs!$B$31)*(1+Inputs!$B$34)
A7: Capacitor EBITDA | B7: =Inputs!$B$8+Inputs!$B$9-B10 | C7: =B7*(1+Inputs!$B$29)+B6*(1+Inputs!$B$29)*Inputs!$B$32*Inputs!$B$13 | D7: =C7*(1+Inputs!$B$30)+C6*(1+Inputs!$B$30)*Inputs!$B$33*Inputs!$B$13 | E7: =D7*(1+Inputs!$B$31)+D6*(1+Inputs!$B$31)*Inputs!$B$34*Inputs!$B$13
A8: Capacitor EBITDA margin | B8: =B7/B6 | C8: =C7/C6 | D8: =D7/D6 | E8: =E7/E6
A9: Other revenue | B9: =Inputs!$B$11-Inputs!$B$10 | C9: =B9*(1+Inputs!$B$35) | D9: =C9*(1+Inputs!$B$35) | E9: =D9*(1+Inputs!$B$35)
A10: Other EBITDA | B10: =B9*Inputs!$B$12 | C10: =C9*Inputs!$B$12 | D10: =D9*Inputs!$B$12 | E10: =E9*Inputs!$B$12
A11: Group revenue | B11: =B6+B9 | C11: =C6+C9 | D11: =D6+D9 | E11: =E6+E9
A12: Group EBITDA | B12: =B7+B10 | C12: =C7+C10 | D12: =D7+D10 | E12: =E7+E10
A13: D&A | B13: =Inputs!B22 | C13: =Inputs!C22 | D13: =Inputs!D22 | E13: =Inputs!E22
A14: Net income (approx.) | B14: =(B12-B13)*(1-Inputs!$B$14) | C14: =(C12-C13)*(1-Inputs!$B$14) | D14: =(D12-D13)*(1-Inputs!$B$14) | E14: =(E12-E13)*(1-Inputs!$B$14)
A15: Capex | B15: =Inputs!B23 | C15: =Inputs!C23 | D15: =Inputs!D23 | E15: =Inputs!E23
A16: Dividends | B16: =Inputs!B24*Inputs!$B$6 | C16: =Inputs!C24*Inputs!$B$6 | D16: =Inputs!D24*Inputs!$B$6 | E16: =Inputs!E24*Inputs!$B$6
A17: Net cash (end) | B17: =Inputs!$B$7+B14+B13-B15-B16 | C17: =B17+C14+C13-C15-C16 | D17: =C17+D14+D13-D15-D16 | E17: =D17+E14+E13-E15-E16
A19: 5-yr mean EBITDA FY3/26-30 | B19: =AVERAGE(Inputs!$B$18,B12:E12)
A20: Exit multiple (x) | B20: =Inputs!B36
A21: Exit EV | B21: =B19*B20
A22: Exit equity value | B22: =B21+E17
A23: Value per share at exit (JPY) | B23: =B22/Inputs!$B$6
A24: Dividends received to exit (JPY) | B24: =SUM(Inputs!B24:E24)
A25: IRR from today | B25: =((B23+B24)/Inputs!$B$5)^(1/Inputs!$B$16)-1
A26: Present value per share at CoE (JPY) | B26: =B23/(1+Inputs!$B$15)^Inputs!$B$16+SUMPRODUCT(Inputs!B24:E24,1/(1+Inputs!$B$15)^{0.5,1.5,2.5,3.5})
A27: Entry price for 20% IRR (JPY) | B27: =(B23+B24)/(1+Inputs!$B$17)^Inputs!$B$16
A28: Probability | B28: =Inputs!B28
A31: Base case
A32: Line | B32: FY3/27 | C32: FY3/28 | D32: FY3/29 | E32: FY3/30
A33: Capacitor revenue | B33: =Inputs!$B$10 | C33: =B33*(1+Inputs!$C$29)*(1+Inputs!$C$32) | D33: =C33*(1+Inputs!$C$30)*(1+Inputs!$C$33) | E33: =D33*(1+Inputs!$C$31)*(1+Inputs!$C$34)
A34: Capacitor EBITDA | B34: =Inputs!$B$8+Inputs!$B$9-B37 | C34: =B34*(1+Inputs!$C$29)+B33*(1+Inputs!$C$29)*Inputs!$C$32*Inputs!$B$13 | D34: =C34*(1+Inputs!$C$30)+C33*(1+Inputs!$C$30)*Inputs!$C$33*Inputs!$B$13 | E34: =D34*(1+Inputs!$C$31)+D33*(1+Inputs!$C$31)*Inputs!$C$34*Inputs!$B$13
A35: Capacitor EBITDA margin | B35: =B34/B33 | C35: =C34/C33 | D35: =D34/D33 | E35: =E34/E33
A36: Other revenue | B36: =Inputs!$B$11-Inputs!$B$10 | C36: =B36*(1+Inputs!$C$35) | D36: =C36*(1+Inputs!$C$35) | E36: =D36*(1+Inputs!$C$35)
A37: Other EBITDA | B37: =B36*Inputs!$B$12 | C37: =C36*Inputs!$B$12 | D37: =D36*Inputs!$B$12 | E37: =E36*Inputs!$B$12
A38: Group revenue | B38: =B33+B36 | C38: =C33+C36 | D38: =D33+D36 | E38: =E33+E36
A39: Group EBITDA | B39: =B34+B37 | C39: =C34+C37 | D39: =D34+D37 | E39: =E34+E37
A40: D&A | B40: =Inputs!B22 | C40: =Inputs!C22 | D40: =Inputs!D22 | E40: =Inputs!E22
A41: Net income (approx.) | B41: =(B39-B40)*(1-Inputs!$B$14) | C41: =(C39-C40)*(1-Inputs!$B$14) | D41: =(D39-D40)*(1-Inputs!$B$14) | E41: =(E39-E40)*(1-Inputs!$B$14)
A42: Capex | B42: =Inputs!B23 | C42: =Inputs!C23 | D42: =Inputs!D23 | E42: =Inputs!E23
A43: Dividends | B43: =Inputs!B24*Inputs!$B$6 | C43: =Inputs!C24*Inputs!$B$6 | D43: =Inputs!D24*Inputs!$B$6 | E43: =Inputs!E24*Inputs!$B$6
A44: Net cash (end) | B44: =Inputs!$B$7+B41+B40-B42-B43 | C44: =B44+C41+C40-C42-C43 | D44: =C44+D41+D40-D42-D43 | E44: =D44+E41+E40-E42-E43
...

Sheet Sensitivity
A1: Sensitivity grids
A2: Grid 1 = the single technical driver: annual MLCC price change x annual volume growth, FY3/28-30, Base other inputs, Base exit multiple. Grid 2 = exit multiple x 5-yr mean EBITDA.
A4: Value per share at exit (JPY): rows = annual capacitor volume growth, columns = annual capacitor price change
A5: vol \ price | B5: -0.1 | C5: -0.05 | D5: -0.02 | E5: 0 | F5: 0.03 | G5: 0.06 | H5: 0.1
A6: -0.05 | B6: =(((Inputs!$B$18)+(Inputs!$B$8+Inputs!$B$9)+((Scenarios!$B$34*(1+$A6)+Scenarios!$B$33*(1+$A6)^1*(1+B$5)^0*B$5*Inputs!$B$13)+Scenarios!$B$36*(1+Inputs!$C$35)^1*Inputs!$B$12)+(((Scenarios!$B$34*(1+$A6)+Scenarios!$B$33*(1+$A6)^1*(1+B$5)^0*B$5*Inputs!$B$13)*(1+$A6)+Scenarios!$B$33*(1+$A6)^2*(1+B$5)^1*B$5*Inputs!$B$13)+Scenarios!$B$36*(1+Inputs!$C$35)^2*Inputs!$B$12)+((((Scenarios!$B$34*(1+$A6)+Scenarios!$B$33*(1+$A6)^1*(1+B$5)^0*B$5*Inputs!$B$13)*(1+$A6)+Scenarios!$B$33*(1+$A6)^2*(1+B$5)^1*B$5*Inputs!$B$13)*(1+$A6)+Scenarios!$B$33*(1+$A6)^3*(1+B$5)^2*B$5*Inputs!$B$13)+Scenarios!$B$36*(1+Inputs!$C$35)^3*Inputs!$B$12))/5*Inputs!$C$36+Scenarios!E44)/Inputs!$B$6 | C6: =(((Inputs!$B$18)+(Inputs!$B$8+Inputs!$B$9)+((Scenarios!$B$34*(1+$A6)+Scenarios!$B$33*(1+$A6)^1*(1+C$5)^0*C$5*Inputs!$B$13)+Scenarios!$B$36*(1+Inputs!$C$35)^1*Inputs!$B$12)+(((Scenarios!$B$34*(1+$A6)+Scenarios!$B$33*(1+$A6)^1*(1+C$5)^0*C$5*Inputs!$B$13)*(1+$A6)+Scenarios!$B$33*(1+$A6)^2*(1+C$5)^1*C$5*Inputs!$B$13)+Scenarios!$B$36*(1+Inputs!$C$35)^2*Inputs!$B$12)+((((Scenarios!$B$34*(1+$A6)+Scenarios!$B$33*(1+$A6)^1*(1+C$5)^0*C$5*Inputs!$B$13)*(1+$A6)+Scenarios!$B$33*(1+$A6)^2*(1+C$5)^1*C$5*Inputs!$B$13)*(1+$A6)+Scenarios!$B$33*(1+$A6)^3*(1+C$5)^2*C$5*Inputs!$B$13)+Scenarios!$B$36*(1+Inputs!$C$35)^3*Inputs!$B$12))/5*Inputs!$C$36+Scenarios!E44)/Inputs!$B$6 | D6: =(((Inputs!$B$18)+(Inputs!$B$8+Inputs!$B$9)+((Scenarios!$B$34*(1+$A6)+Scenarios!$B$33*(1+$A6)^1*(1+D$5)^0*D$5*Inputs!$B$13)+Scenarios!$B$36*(1+Inputs!$C$35)^1*Inputs!$B$12)+(((Scenarios!$B$34*(1+$A6)+Scenarios!$B$33*(1+$A6)^1*(1+D$5)^0*D$5*Inputs!$B$13)*(1+$A6)+Scenarios!$B$33*(1+$A6)^2*(1+D$5)^1*D$5*Inputs!$B$13)+Scenarios!$B$36*(1+Inputs!$C$35)^2*Inputs!$B$12)+((((Scenarios!$B$34*(1+$A6)+Scenarios!$B$33*(1+$A6)^1*(1+D$5)^0*D$5*Inputs!$B$13)*(1+$A6)+Scenarios!$B$33*(1+$A6)^2*(1+D$5)^1*D$5*Inputs!$B$13)*(1+$A6)+Scenarios!$B$33*(1+$A6)^3*(1+D$5)^2*D$5*Inputs!$B$13)+Scenarios!$B$36*(1+Inputs!$C$35)^3*Inputs!$B$12))/5*Inputs!$C$36+Scenarios!E44)/Inputs!$B$6 | E6: =(((Inputs!$B$18)+(Inputs!$B$8+Inputs!$B$9)+((Scenarios!$B$34*(1+$A6)+Scenarios!$B$33*(1+$A6)^1*(1+E$5)^0*E$5*Inputs!$B$13)+Scenarios!$B$36*(1+Inputs!$C$35)^1*Inputs!$B$12)+(((Scenarios!$B$34*(1+$A6)+Scenarios!$B$33*(1+$A6)^1*(1+E$5)^0*E$5*Inputs!$B$13)*(1+$A6)+Scenarios!$B$33*(1+$A6)^2*(1+E$5)^1*E$5*Inputs!$B$13)+Scenarios!$B$36*(1+Inputs!$C$35)^2*Inputs!$B$12)+((((Scenarios!$B$34*(1+$A6)+Scenarios!$B$33*(1+$A6)^1*(1+E$5)^0*E$5*Inputs!$B$13)*(1+$A6)+Scenarios!$B$33*(1+$A6)^2*(1+E$5)^1*E$5*Inputs!$B$13)*(1+$A6)+Scenarios!$B$33*(1+$A6)^3*(1+E$5)^2*E$5*Inputs!$B$13)+Scenarios!$B$36*(1+Inputs!$C$35)^3*Inputs!$B$12))/5*Inputs!$C$36+Scenarios!E44)/Inputs!$B$6 | F6: =(((Inputs!$B$18)+(Inputs!$B$8+Inputs!$B$9)+((Scenarios!$B$34*(1+$A6)+Scenarios!$B$33*(1+$A6)^1*(1+F$5)^0*F$5*Inputs!$B$13)+Scenarios!$B$36*(1+Inputs!$C$35)^1*Inputs!$B$12)+(((Scenarios!$B$34*(1+$A6)+Scenarios!$B$33*(1+$A6)^1*(1+F$5)^0*F$5*Inputs!$B$13)*(1+$A6)+Scenarios!$B$33*(1+$A6)^2*(1+F$5)^1*F$5*Inputs!$B$13)+Scenarios!$B$36*(1+Inputs!$C$35)^2*Inputs!$B$12)+((((Scenarios!$B$34*(1+$A6)+Scenarios!$B$33*(1+$A6)^1*(1+F$5)^0*F$5*Inputs!$B$13)*(1+$A6)+Scenarios!$B$33*(1+$A6)^2*(1+F$5)^1*F$5*Inputs!$B$13)*(1+$A6)+Scenarios!$B$33*(1+$A6)^3*(1+F$5)^2*F$5*Inputs!$B$13)+Scenarios!$B$36*(1+Inputs!$C$35)^3*Inputs!$B$12))/5*Inputs!$C$36+Scenarios!E44)/Inputs!$B$6 | G6: =(((Inputs!$B$18)+(Inputs!$B$8+Inputs!$B$9)+((Scenarios!$B$34*(1+$A6)+Scenarios!$B$33*(1+$A6)^1*(1+G$5)^0*G$5*Inputs!$B$13)+Scenarios!$B$36*(1+Inputs!$C$35)^1*Inputs!$B$12)+(((Scenarios!$B$34*(1+$A6)+Scenarios!$B$33*(1+$A6)^1*(1+G$5)^0*G$5*Inputs!$B$13)*(1+$A6)+Scenarios!$B$33*(1+$A6)^2*(1+G$5)^1*G$5*Inputs!$B$13)+Scenarios!$B$36*(1+Inputs!$C$35)^2*Inputs!$B$12)+((((Scenarios!$B$34*(1+$A6)+Scenarios!$B$33*(1+$A6)^1*(1+G$5)^0*G$5*Inputs!$B$13)*(1+$A6)+Scenarios!$B$33*(1+$A6)^2*(1+G$5)^1*G$5*Inputs!$B$13)*(1+$A6)+Scenarios!$B$33*(1+$A6)^3*(1+G$5)^2*G$5*Inputs!$B$13)+Scenarios!$B$36*(1+Inputs!$C$35)^3*Inputs!$B$12))/5*Inputs!$C$36+Scenarios!E44)/Inputs!$B$6 | H6: =(((Inputs!$B$18)+(Inputs!$B$8+Inputs!$B$9)+((Scenarios!$B$34*(1+$A6)+Scenarios!$B$33*(1+$A6)^1*(1+H$5)^0*H$5*Inputs!$B$13)+Scenarios!$B$36*(1+Inputs!$C$35)^1*Inputs!$B$12)+(((Scenarios!$B$34*(1+$A6)+Scenarios!$B$33*(1+$A6)^1*(1+H$5)^0*H$5*Inputs!$B$13)*(1+$A6)+Scenarios!$B$33*(1+$A6)^2*(1+H$5)^1*H$5*Inputs!$B$13)+Scenarios!$B$36*(1+Inputs!$C$35)^2*Inputs!$B$12)+((((Scenarios!$B$34*(1+$A6)+Scenarios!$B$33*(1+$A6)^1*(1+H$5)^0*H$5*Inputs!$B$13)*(1+$A6)+Scenarios!$B$33*(1+$A6)^2*(1+H$5)^1*H$5*Inputs!$B$13)*(1+$A6)+Scenarios!$B$33*(1+$A6)^3*(1+H$5)^2*H$5*Inputs!$B$13)+Scenarios!$B$36*(1+Inputs!$C$35)^3*Inputs!$B$12))/5*Inputs!$C$36+Scenarios!E44)/Inputs!$B$6
A7: 0 | B7: =(((Inputs!$B$18)+(Inputs!$B$8+Inputs!$B$9)+((Scenarios!$B$34*(1+$A7)+Scenarios!$B$33*(1+$A7)^1*(1+B$5)^0*B$5*Inputs!$B$13)+Scenarios!$B$36*(1+Inputs!$C$35)^1*Inputs!$B$12)+(((Scenarios!$B$34*(1+$A7)+Scenarios!$B$33*(1+$A7)^1*(1+B$5)^0*B$5*Inputs!$B$13)*(1+$A7)+Scenarios!$B$33*(1+$A7)^2*(1+B$5)^1*B$5*Inputs!$B$13)+Scenarios!$B$36*(1+Inputs!$C$35)^2*Inputs!$B$12)+((((Scenarios!$B$34*(1+$A7)+Scenarios!$B$33*(1+$A7)^1*(1+B$5)^0*B$5*Inputs!$B$13)*(1+$A7)+Scenarios!$B$33*(1+$A7)^2*(1+B$5)^1*B$5*Inputs!$B$13)*(1+$A7)+Scenarios!$B$33*(1+$A7)^3*(1+B$5)^2*B$5*Inputs!$B$13)+Scenarios!$B$36*(1+Inputs!$C$35)^3*Inputs!$B$12))/5*Inputs!$C$36+Scenarios!E44)/Inputs!$B$6 | C7: =(((Inputs!$B$18)+(Inputs!$B$8+Inputs!$B$9)+((Scenarios!$B$34*(1+$A7)+Scenarios!$B$33*(1+$A7)^1*(1+C$5)^0*C$5*Inputs!$B$13)+Scenarios!$B$36*(1+Inputs!$C$35)^1*Inputs!$B$12)+(((Scenarios!$B$34*(1+$A7)+Scenarios!$B$33*(1+$A7)^1*(1+C$5)^0*C$5*Inputs!$B$13)*(1+$A7)+Scenarios!$B$33*(1+$A7)^2*(1+C$5)^1*C$5*Inputs!$B$13)+Scenarios!$B$36*(1+Inputs!$C$35)^2*Inputs!$B$12)+((((Scenarios!$B$34*(1+$A7)+Scenarios!$B$33*(1+$A7)^1*(1+C$5)^0*C$5*Inputs!$B$13)*(1+$A7)+Scenarios!$B$33*(1+$A7)^2*(1+C$5)^1*C$5*Inputs!$B$13)*(1+$A7)+Scenarios!$B$33*(1+$A7)^3*(1+C$5)^2*C$5*Inputs!$B$13)+Scenarios!$B$36*(1+Inputs!$C$35)^3*Inputs!$B$12))/5*Inputs!$C$36+Scenarios!E44)/Inputs!$B$6 | D7: =(((Inputs!$B$18)+(Inputs!$B$8+Inputs!$B$9)+((Scenarios!$B$34*(1+$A7)+Scenarios!$B$33*(1+$A7)^1*(1+D$5)^0*D$5*Inputs!$B$13)+Scenarios!$B$36*(1+Inputs!$C$35)^1*Inputs!$B$12)+(((Scenarios!$B$34*(1+$A7)+Scenarios!$B$33*(1+$A7)^1*(1+D$5)^0*D$5*Inputs!$B$13)*(1+$A7)+Scenarios!$B$33*(1+$A7)^2*(1+D$5)^1*D$5*Inputs!$B$13)+Scenarios!$B$36*(1+Inputs!$C$35)^2*Inputs!$B$12)+((((Scenarios!$B$34*(1+$A7)+Scenarios!$B$33*(1+$A7)^1*(1+D$5)^0*D$5*Inputs!$B$13)*(1+$A7)+Scenarios!$B$33*(1+$A7)^2*(1+D$5)^1*D$5*Inputs!$B$13)*(1+$A7)+Scenarios!$B$33*(1+$A7)^3*(1+D$5)^2*D$5*Inputs!$B$13)+Scenarios!$B$36*(1+Inputs!$C$35)^3*Inputs!$B$12))/5*Inputs!$C$36+Scenarios!E44)/Inputs!$B$6 | E7: =(((Inputs!$B$18)+(Inputs!$B$8+Inputs!$B$9)+((Scenarios!$B$34*(1+$A7)+Scenarios!$B$33*(1+$A7)^1*(1+E$5)^0*E$5*Inputs!$B$13)+Scenarios!$B$36*(1+Inputs!$C$35)^1*Inputs!$B$12)+(((Scenarios!$B$34*(1+$A7)+Scenarios!$B$33*(1+$A7)^1*(1+E$5)^0*E$5*Inputs!$B$13)*(1+$A7)+Scenarios!$B$33*(1+$A7)^2*(1+E$5)^1*E$5*Inputs!$B$13)+Scenarios!$B$36*(1+Inputs!$C$35)^2*Inputs!$B$12)+((((Scenarios!$B$34*(1+$A7)+Scenarios!$B$33*(1+$A7)^1*(1+E$5)^0*E$5*Inputs!$B$13)*(1+$A7)+Scenarios!$B$33*(1+$A7)^2*(1+E$5)^1*E$5*Inputs!$B$13)*(1+$A7)+Scenarios!$B$33*(1+$A7)^3*(1+E$5)^2*E$5*Inputs!$B$13)+Scenarios!$B$36*(1+Inputs!$C$35)^3*Inputs!$B$12))/5*Inputs!$C$36+Scenarios!E44)/Inputs!$B$6 | F7: =(((Inputs!$B$18)+(Inputs!$B$8+Inputs!$B$9)+((Scenarios!$B$34*(1+$A7)+Scenarios!$B$33*(1+$A7)^1*(1+F$5)^0*F$5*Inputs!$B$13)+Scenarios!$B$36*(1+Inputs!$C$35)^1*Inputs!$B$12)+(((Scenarios!$B$34*(1+$A7)+Scenarios!$B$33*(1+$A7)^1*(1+F$5)^0*F$5*Inputs!$B$13)*(1+$A7)+Scenarios!$B$33*(1+$A7)^2*(1+F$5)^1*F$5*Inputs!$B$13)+Scenarios!$B$36*(1+Inputs!$C$35)^2*Inputs!$B$12)+((((Scenarios!$B$34*(1+$A7)+Scenarios!$B$33*(1+$A7)^1*(1+F$5)^0*F$5*Inputs!$B$13)*(1+$A7)+Scenarios!$B$33*(1+$A7)^2*(1+F$5)^1*F$5*Inputs!$B$13)*(1+$A7)+Scenarios!$B$33*(1+$A7)^3*(1+F$5)^2*F$5*Inputs!$B$13)+Scenarios!$B$36*(1+Inputs!$C$35)^3*Inputs!$B$12))/5*Inputs!$C$36+Scenarios!E44)/Inputs!$B$6 | G7: =(((Inputs!$B$18)+(Inputs!$B$8+Inputs!$B$9)+((Scenarios!$B$34*(1+$A7)+Scenarios!$B$33*(1+$A7)^1*(1+G$5)^0*G$5*Inputs!$B$13)+Scenarios!$B$36*(1+Inputs!$C$35)^1*Inputs!$B$12)+(((Scenarios!$B$34*(1+$A7)+Scenarios!$B$33*(1+$A7)^1*(1+G$5)^0*G$5*Inputs!$B$13)*(1+$A7)+Scenarios!$B$33*(1+$A7)^2*(1+G$5)^1*G$5*Inputs!$B$13)+Scenarios!$B$36*(1+Inputs!$C$35)^2*Inputs!$B$12)+((((Scenarios!$B$34*(1+$A7)+Scenarios!$B$33*(1+$A7)^1*(1+G$5)^0*G$5*Inputs!$B$13)*(1+$A7)+Scenarios!$B$33*(1+$A7)^2*(1+G$5)^1*G$5*Inputs!$B$13)*(1+$A7)+Scenarios!$B$33*(1+$A7)^3*(1+G$5)^2*G$5*Inputs!$B$13)+Scenarios!$B$36*(1+Inputs!$C$35)^3*Inputs!$B$12))/5*Inputs!$C$36+Scenarios!E44)/Inputs!$B$6 | H7: =(((Inputs!$B$18)+(Inputs!$B$8+Inputs!$B$9)+((Scenarios!$B$34*(1+$A7)+Scenarios!$B$33*(1+$A7)^1*(1+H$5)^0*H$5*Inputs!$B$13)+Scenarios!$B$36*(1+Inputs!$C$35)^1*Inputs!$B$12)+(((Scenarios!$B$34*(1+$A7)+Scenarios!$B$33*(1+$A7)^1*(1+H$5)^0*H$5*Inputs!$B$13)*(1+$A7)+Scenarios!$B$33*(1+$A7)^2*(1+H$5)^1*H$5*Inputs!$B$13)+Scenarios!$B$36*(1+Inputs!$C$35)^2*Inputs!$B$12)+((((Scenarios!$B$34*(1+$A7)+Scenarios!$B$33*(1+$A7)^1*(1+H$5)^0*H$5*Inputs!$B$13)*(1+$A7)+Scenarios!$B$33*(1+$A7)^2*(1+H$5)^1*H$5*Inputs!$B$13)*(1+$A7)+Scenarios!$B$33*(1+$A7)^3*(1+H$5)^2*H$5*Inputs!$B$13)+Scenarios!$B$36*(1+Inputs!$C$35)^3*Inputs!$B$12))/5*Inputs!$C$36+Scenarios!E44)/Inputs!$B$6
A8: 0.05 | B8: =(((Inputs!$B$18)+(Inputs!$B$8+Inputs!$B$9)+((Scenarios!$B$34*(1+$A8)+Scenarios!$B$33*(1+$A8)^1*(1+B$5)^0*B$5*Inputs!$B$13)+Scenarios!$B$36*(1+Inputs!$C$35)^1*Inputs!$B$12)+(((Scenarios!$B$34*(1+$A8)+Scenarios!$B$33*(1+$A8)^1*(1+B$5)^0*B$5*Inputs!$B$13)*(1+$A8)+Scenarios!$B$33*(1+$A8)^2*(1+B$5)^1*B$5*Inputs!$B$13)+Scenarios!$B$36*(1+Inputs!$C$35)^2*Inputs!$B$12)+((((Scenarios!$B$34*(1+$A8)+Scenarios!$B$33*(1+$A8)^1*(1+B$5)^0*B$5*Inputs!$B$13)*(1+$A8)+Scenarios!$B$33*(1+$A8)^2*(1+B$5)^1*B$5*Inputs!$B$13)*(1+$A8)+Scenarios!$B$33*(1+$A8)^3*(1+B$5)^2*B$5*Inputs!$B$13)+Scenarios!$B$36*(1+Inputs!$C$35)^3*Inputs!$B$12))/5*Inputs!$C$36+Scenarios!E44)/Inputs!$B$6 | C8: =(((Inputs!$B$18)+(Inputs!$B$8+Inputs!$B$9)+((Scenarios!$B$34*(1+$A8)+Scenarios!$B$33*(1+$A8)^1*(1+C$5)^0*C$5*Inputs!$B$13)+Scenarios!$B$36*(1+Inputs!$C$35)^1*Inputs!$B$12)+(((Scenarios!$B$34*(1+$A8)+Scenarios!$B$33*(1+$A8)^1*(1+C$5)^0*C$5*Inputs!$B$13)*(1+$A8)+Scenarios!$B$33*(1+$A8)^2*(1+C$5)^1*C$5*Inputs!$B$13)+Scenarios!$B$36*(1+Inputs!$C$35)^2*Inputs!$B$12)+((((Scenarios!$B$34*(1+$A8)+Scenarios!$B$33*(1+$A8)^1*(1+C$5)^0*C$5*Inputs!$B$13)*(1+$A8)+Scenarios!$B$33*(1+$A8)^2*(1+C$5)^1*C$5*Inputs!$B$13)*(1+$A8)+Scenarios!$B$33*(1+$A8)^3*(1+C$5)^2*C$5*Inputs!$B$13)+Scenarios!$B$36*(1+Inputs!$C$35)^3*Inputs!$B$12))/5*Inputs!$C$36+Scenarios!E44)/Inputs!$B$6 | D8: =(((Inputs!$B$18)+(Inputs!$B$8+Inputs!$B$9)+((Scenarios!$B$34*(1+$A8)+Scenarios!$B$33*(1+$A8)^1*(1+D$5)^0*D$5*Inputs!$B$13)+Scenarios!$B$36*(1+Inputs!$C$35)^1*Inputs!$B$12)+(((Scenarios!$B$34*(1+$A8)+Scenarios!$B$33*(1+$A8)^1*(1+D$5)^0*D$5*Inputs!$B$13)*(1+$A8)+Scenarios!$B$33*(1+$A8)^2*(1+D$5)^1*D$5*Inputs!$B$13)+Scenarios!$B$36*(1+Inputs!$C$35)^2*Inputs!$B$12)+((((Scenarios!$B$34*(1+$A8)+Scenarios!$B$33*(1+$A8)^1*(1+D$5)^0*D$5*Inputs!$B$13)*(1+$A8)+Scenarios!$B$33*(1+$A8)^2*(1+D$5)^1*D$5*Inputs!$B$13)*(1+$A8)+Scenarios!$B$33*(1+$A8)^3*(1+D$5)^2*D$5*Inputs!$B$13)+Scenarios!$B$36*(1+Inputs!$C$35)^3*Inputs!$B$12))/5*Inputs!$C$36+Scenarios!E44)/Inputs!$B$6 | E8: =(((Inputs!$B$18)+(Inputs!$B$8+Inputs!$B$9)+((Scenarios!$B$34*(1+$A8)+Scenarios!$B$33*(1+$A8)^1*(1+E$5)^0*E$5*Inputs!$B$13)+Scenarios!$B$36*(1+Inputs!$C$35)^1*Inputs!$B$12)+(((Scenarios!$B$34*(1+$A8)+Scenarios!$B$33*(1+$A8)^1*(1+E$5)^0*E$5*Inputs!$B$13)*(1+$A8)+Scenarios!$B$33*(1+$A8)^2*(1+E$5)^1*E$5*Inputs!$B$13)+Scenarios!$B$36*(1+Inputs!$C$35)^2*Inputs!$B$12)+((((Scenarios!$B$34*(1+$A8)+Scenarios!$B$33*(1+$A8)^1*(1+E$5)^0*E$5*Inputs!$B$13)*(1+$A8)+Scenarios!$B$33*(1+$A8)^2*(1+E$5)^1*E$5*Inputs!$B$13)*(1+$A8)+Scenarios!$B$33*(1+$A8)^3*(1+E$5)^2*E$5*Inputs!$B$13)+Scenarios!$B$36*(1+Inputs!$C$35)^3*Inputs!$B$12))/5*Inputs!$C$36+Scenarios!E44)/Inputs!$B$6 | F8: =(((Inputs!$B$18)+(Inputs!$B$8+Inputs!$B$9)+((Scenarios!$B$34*(1+$A8)+Scenarios!$B$33*(1+$A8)^1*(1+F$5)^0*F$5*Inputs!$B$13)+Scenarios!$B$36*(1+Inputs!$C$35)^1*Inputs!$B$12)+(((Scenarios!$B$34*(1+$A8)+Scenarios!$B$33*(1+$A8)^1*(1+F$5)^0*F$5*Inputs!$B$13)*(1+$A8)+Scenarios!$B$33*(1+$A8)^2*(1+F$5)^1*F$5*Inputs!$B$13)+Scenarios!$B$36*(1+Inputs!$C$35)^2*Inputs!$B$12)+((((Scenarios!$B$34*(1+$A8)+Scenarios!$B$33*(1+$A8)^1*(1+F$5)^0*F$5*Inputs!$B$13)*(1+$A8)+Scenarios!$B$33*(1+$A8)^2*(1+F$5)^1*F$5*Inputs!$B$13)*(1+$A8)+Scenarios!$B$33*(1+$A8)^3*(1+F$5)^2*F$5*Inputs!$B$13)+Scenarios!$B$36*(1+Inputs!$C$35)^3*Inputs!$B$12))/5*Inputs!$C$36+Scenarios!E44)/Inputs!$B$6 | G8: =(((Inputs!$B$18)+(Inputs!$B$8+Inputs!$B$9)+((Scenarios!$B$34*(1+$A8)+Scenarios!$B$33*(1+$A8)^1*(1+G$5)^0*G$5*Inputs!$B$13)+Scenarios!$B$36*(1+Inputs!$C$35)^1*Inputs!$B$12)+(((Scenarios!$B$34*(1+$A8)+Scenarios!$B$33*(1+$A8)^1*(1+G$5)^0*G$5*Inputs!$B$13)*(1+$A8)+Scenarios!$B$33*(1+$A8)^2*(1+G$5)^1*G$5*Inputs!$B$13)+Scenarios!$B$36*(1+Inputs!$C$35)^2*Inputs!$B$12)+((((Scenarios!$B$34*(1+$A8)+Scenarios!$B$33*(1+$A8)^1*(1+G$5)^0*G$5*Inputs!$B$13)*(1+$A8)+Scenarios!$B$33*(1+$A8)^2*(1+G$5)^1*G$5*Inputs!$B$13)*(1+$A8)+Scenarios!$B$33*(1+$A8)^3*(1+G$5)^2*G$5*Inputs!$B$13)+Scenarios!$B$36*(1+Inputs!$C$35)^3*Inputs!$B$12))/5*Inputs!$C$36+Scenarios!E44)/Inputs!$B$6 | H8: =(((Inputs!$B$18)+(Inputs!$B$8+Inputs!$B$9)+((Scenarios!$B$34*(1+$A8)+Scenarios!$B$33*(1+$A8)^1*(1+H$5)^0*H$5*Inputs!$B$13)+Scenarios!$B$36*(1+Inputs!$C$35)^1*Inputs!$B$12)+(((Scenarios!$B$34*(1+$A8)+Scenarios!$B$33*(1+$A8)^1*(1+H$5)^0*H$5*Inputs!$B$13)*(1+$A8)+Scenarios!$B$33*(1+$A8)^2*(1+H$5)^1*H$5*Inputs!$B$13)+Scenarios!$B$36*(1+Inputs!$C$35)^2*Inputs!$B$12)+((((Scenarios!$B$34*(1+$A8)+Scenarios!$B$33*(1+$A8)^1*(1+H$5)^0*H$5*Inputs!$B$13)*(1+$A8)+Scenarios!$B$33*(1+$A8)^2*(1+H$5)^1*H$5*Inputs!$B$13)*(1+$A8)+Scenarios!$B$33*(1+$A8)^3*(1+H$5)^2*H$5*Inputs!$B$13)+Scenarios!$B$36*(1+Inputs!$C$35)^3*Inputs!$B$12))/5*Inputs!$C$36+Scenarios!E44)/Inputs!$B$6
A9: 0.1 | B9: =(((Inputs!$B$18)+(Inputs!$B$8+Inputs!$B$9)+((Scenarios!$B$34*(1+$A9)+Scenarios!$B$33*(1+$A9)^1*(1+B$5)^0*B$5*Inputs!$B$13)+Scenarios!$B$36*(1+Inputs!$C$35)^1*Inputs!$B$12)+(((Scenarios!$B$34*(1+$A9)+Scenarios!$B$33*(1+$A9)^1*(1+B$5)^0*B$5*Inputs!$B$13)*(1+$A9)+Scenarios!$B$33*(1+$A9)^2*(1+B$5)^1*B$5*Inputs!$B$13)+Scenarios!$B$36*(1+Inputs!$C$35)^2*Inputs!$B$12)+((((Scenarios!$B$34*(1+$A9)+Scenarios!$B$33*(1+$A9)^1*(1+B$5)^0*B$5*Inputs!$B$13)*(1+$A9)+Scenarios!$B$33*(1+$A9)^2*(1+B$5)^1*B$5*Inputs!$B$13)*(1+$A9)+Scenarios!$B$33*(1+$A9)^3*(1+B$5)^2*B$5*Inputs!$B$13)+Scenarios!$B$36*(1+Inputs!$C$35)^3*Inputs!$B$12))/5*Inputs!$C$36+Scenarios!E44)/Inputs!$B$6 | C9: =(((Inputs!$B$18)+(Inputs!$B$8+Inputs!$B$9)+((Scenarios!$B$34*(1+$A9)+Scenarios!$B$33*(1+$A9)^1*(1+C$5)^0*C$5*Inputs!$B$13)+Scenarios!$B$36*(1+Inputs!$C$35)^1*Inputs!$B$12)+(((Scenarios!$B$34*(1+$A9)+Scenarios!$B$33*(1+$A9)^1*(1+C$5)^0*C$5*Inputs!$B$13)*(1+$A9)+Scenarios!$B$33*(1+$A9)^2*(1+C$5)^1*C$5*Inputs!$B$13)+Scenarios!$B$36*(1+Inputs!$C$35)^2*Inputs!$B$12)+((((Scenarios!$B$34*(1+$A9)+Scenarios!$B$33*(1+$A9)^1*(1+C$5)^0*C$5*Inputs!$B$13)*(1+$A9)+Scenarios!$B$33*(1+$A9)^2*(1+C$5)^1*C$5*Inputs!$B$13)*(1+$A9)+Scenarios!$B$33*(1+$A9)^3*(1+C$5)^2*C$5*Inputs!$B$13)+Scenarios!$B$36*(1+Inputs!$C$35)^3*Inputs!$B$12))/5*Inputs!$C$36+Scenarios!E44)/Inputs!$B$6 | D9: =(((Inputs!$B$18)+(Inputs!$B$8+Inputs!$B$9)+((Scenarios!$B$34*(1+$A9)+Scenarios!$B$33*(1+$A9)^1*(1+D$5)^0*D$5*Inputs!$B$13)+Scenarios!$B$36*(1+Inputs!$C$35)^1*Inputs!$B$12)+(((Scenarios!$B$34*(1+$A9)+Scenarios!$B$33*(1+$A9)^1*(1+D$5)^0*D$5*Inputs!$B$13)*(1+$A9)+Scenarios!$B$33*(1+$A9)^2*(1+D$5)^1*D$5*Inputs!$B$13)+Scenarios!$B$36*(1+Inputs!$C$35)^2*Inputs!$B$12)+((((Scenarios!$B$34*(1+$A9)+Scenarios!$B$33*(1+$A9)^1*(1+D$5)^0*D$5*Inputs!$B$13)*(1+$A9)+Scenarios!$B$33*(1+$A9)^2*(1+D$5)^1*D$5*Inputs!$B$13)*(1+$A9)+Scenarios!$B$33*(1+$A9)^3*(1+D$5)^2*D$5*Inputs!$B$13)+Scenarios!$B$36*(1+Inputs!$C$35)^3*Inputs!$B$12))/5*Inputs!$C$36+Scenarios!E44)/Inputs!$B$6 | E9: =(((Inputs!$B$18)+(Inputs!$B$8+Inputs!$B$9)+((Scenarios!$B$34*(1+$A9)+Scenarios!$B$33*(1+$A9)^1*(1+E$5)^0*E$5*Inputs!$B$13)+Scenarios!$B$36*(1+Inputs!$C$35)^1*Inputs!$B$12)+(((Scenarios!$B$34*(1+$A9)+Scenarios!$B$33*(1+$A9)^1*(1+E$5)^0*E$5*Inputs!$B$13)*(1+$A9)+Scenarios!$B$33*(1+$A9)^2*(1+E$5)^1*E$5*Inputs!$B$13)+Scenarios!$B$36*(1+Inputs!$C$35)^2*Inputs!$B$12)+((((Scenarios!$B$34*(1+$A9)+Scenarios!$B$33*(1+$A9)^1*(1+E$5)^0*E$5*Inputs!$B$13)*(1+$A9)+Scenarios!$B$33*(1+$A9)^2*(1+E$5)^1*E$5*Inputs!$B$13)*(1+$A9)+Scenarios!$B$33*(1+$A9)^3*(1+E$5)^2*E$5*Inputs!$B$13)+Scenarios!$B$36*(1+Inputs!$C$35)^3*Inputs!$B$12))/5*Inputs!$C$36+Scenarios!E44)/Inputs!$B$6 | F9: =(((Inputs!$B$18)+(Inputs!$B$8+Inputs!$B$9)+((Scenarios!$B$34*(1+$A9)+Scenarios!$B$33*(1+$A9)^1*(1+F$5)^0*F$5*Inputs!$B$13)+Scenarios!$B$36*(1+Inputs!$C$35)^1*Inputs!$B$12)+(((Scenarios!$B$34*(1+$A9)+Scenarios!$B$33*(1+$A9)^1*(1+F$5)^0*F$5*Inputs!$B$13)*(1+$A9)+Scenarios!$B$33*(1+$A9)^2*(1+F$5)^1*F$5*Inputs!$B$13)+Scenarios!$B$36*(1+Inputs!$C$35)^2*Inputs!$B$12)+((((Scenarios!$B$34*(1+$A9)+Scenarios!$B$33*(1+$A9)^1*(1+F$5)^0*F$5*Inputs!$B$13)*(1+$A9)+Scenarios!$B$33*(1+$A9)^2*(1+F$5)^1*F$5*Inputs!$B$13)*(1+$A9)+Scenarios!$B$33*(1+$A9)^3*(1+F$5)^2*F$5*Inputs!$B$13)+Scenarios!$B$36*(1+Inputs!$C$35)^3*Inputs!$B$12))/5*Inputs!$C$36+Scenarios!E44)/Inputs!$B$6 | G9: =(((Inputs!$B$18)+(Inputs!$B$8+Inputs!$B$9)+((Scenarios!$B$34*(1+$A9)+Scenarios!$B$33*(1+$A9)^1*(1+G$5)^0*G$5*Inputs!$B$13)+Scenarios!$B$36*(1+Inputs!$C$35)^1*Inputs!$B$12)+(((Scenarios!$B$34*(1+$A9)+Scenarios!$B$33*(1+$A9)^1*(1+G$5)^0*G$5*Inputs!$B$13)*(1+$A9)+Scenarios!$B$33*(1+$A9)^2*(1+G$5)^1*G$5*Inputs!$B$13)+Scenarios!$B$36*(1+Inputs!$C$35)^2*Inputs!$B$12)+((((Scenarios!$B$34*(1+$A9)+Scenarios!$B$33*(1+$A9)^1*(1+G$5)^0*G$5*Inputs!$B$13)*(1+$A9)+Scenarios!$B$33*(1+$A9)^2*(1+G$5)^1*G$5*Inputs!$B$13)*(1+$A9)+Scenarios!$B$33*(1+$A9)^3*(1+G$5)^2*G$5*Inputs!$B$13)+Scenarios!$B$36*(1+Inputs!$C$35)^3*Inputs!$B$12))/5*Inputs!$C$36+Scenarios!E44)/Inputs!$B$6 | H9: =(((Inputs!$B$18)+(Inputs!$B$8+Inputs!$B$9)+((Scenarios!$B$34*(1+$A9)+Scenarios!$B$33*(1+$A9)^1*(1+H$5)^0*H$5*Inputs!$B$13)+Scenarios!$B$36*(1+Inputs!$C$35)^1*Inputs!$B$12)+(((Scenarios!$B$34*(1+$A9)+Scenarios!$B$33*(1+$A9)^1*(1+H$5)^0*H$5*Inputs!$B$13)*(1+$A9)+Scenarios!$B$33*(1+$A9)^2*(1+H$5)^1*H$5*Inputs!$B$13)+Scenarios!$B$36*(1+Inputs!$C$35)^2*Inputs!$B$12)+((((Scenarios!$B$34*(1+$A9)+Scenarios!$B$33*(1+$A9)^1*(1+H$5)^0*H$5*Inputs!$B$13)*(1+$A9)+Scenarios!$B$33*(1+$A9)^2*(1+H$5)^1*H$5*Inputs!$B$13)*(1+$A9)+Scenarios!$B$33*(1+$A9)^3*(1+H$5)^2*H$5*Inputs!$B$13)+Scenarios!$B$36*(1+Inputs!$C$35)^3*Inputs!$B$12))/5*Inputs!$C$36+Scenarios!E44)/Inputs!$B$6
A10: 0.15 | B10: =(((Inputs!$B$18)+(Inputs!$B$8+Inputs!$B$9)+((Scenarios!$B$34*(1+$A10)+Scenarios!$B$33*(1+$A10)^1*(1+B$5)^0*B$5*Inputs!$B$13)+Scenarios!$B$36*(1+Inputs!$C$35)^1*Inputs!$B$12)+(((Scenarios!$B$34*(1+$A10)+Scenarios!$B$33*(1+$A10)^1*(1+B$5)^0*B$5*Inputs!$B$13)*(1+$A10)+Scenarios!$B$33*(1+$A10)^2*(1+B$5)^1*B$5*Inputs!$B$13)+Scenarios!$B$36*(1+Inputs!$C$35)^2*Inputs!$B$12)+((((Scenarios!$B$34*(1+$A10)+Scenarios!$B$33*(1+$A10)^1*(1+B$5)^0*B$5*Inputs!$B$13)*(1+$A10)+Scenarios!$B$33*(1+$A10)^2*(1+B$5)^1*B$5*Inputs!$B$13)*(1+$A10)+Scenarios!$B$33*(1+$A10)^3*(1+B$5)^2*B$5*Inputs!$B$13)+Scenarios!$B$36*(1+Inputs!$C$35)^3*Inputs!$B$12))/5*Inputs!$C$36+Scenarios!E44)/Inputs!$B$6 | C10: =(((Inputs!$B$18)+(Inputs!$B$8+Inputs!$B$9)+((Scenarios!$B$34*(1+$A10)+Scenarios!$B$33*(1+$A10)^1*(1+C$5)^0*C$5*Inputs!$B$13)+Scenarios!$B$36*(1+Inputs!$C$35)^1*Inputs!$B$12)+(((Scenarios!$B$34*(1+$A10)+Scenarios!$B$33*(1+$A10)^1*(1+C$5)^0*C$5*Inputs!$B$13)*(1+$A10)+Scenarios!$B$33*(1+$A10)^2*(1+C$5)^1*C$5*Inputs!$B$13)+Scenarios!$B$36*(1+Inputs!$C$35)^2*Inputs!$B$12)+((((Scenarios!$B$34*(1+$A10)+Scenarios!$B$33*(1+$A10)^1*(1+C$5)^0*C$5*Inputs!$B$13)*(1+$A10)+Scenarios!$B$33*(1+$A10)^2*(1+C$5)^1*C$5*Inputs!$B$13)*(1+$A10)+Scenarios!$B$33*(1+$A10)^3*(1+C$5)^2*C$5*Inputs!$B$13)+Scenarios!$B$36*(1+Inputs!$C$35)^3*Inputs!$B$12))/5*Inputs!$C$36+Scenarios!E44)/Inputs!$B$6 | D10: =(((Inputs!$B$18)+(Inputs!$B$8+Inputs!$B$9)+((Scenarios!$B$34*(1+$A10)+Scenarios!$B$33*(1+$A10)^1*(1+D$5)^0*D$5*Inputs!$B$13)+Scenarios!$B$36*(1+Inputs!$C$35)^1*Inputs!$B$12)+(((Scenarios!$B$34*(1+$A10)+Scenarios!$B$33*(1+$A10)^1*(1+D$5)^0*D$5*Inputs!$B$13)*(1+$A10)+Scenarios!$B$33*(1+$A10)^2*(1+D$5)^1*D$5*Inputs!$B$13)+Scenarios!$B$36*(1+Inputs!$C$35)^2*Inputs!$B$12)+((((Scenarios!$B$34*(1+$A10)+Scenarios!$B$33*(1+$A10)^1*(1+D$5)^0*D$5*Inputs!$B$13)*(1+$A10)+Scenarios!$B$33*(1+$A10)^2*(1+D$5)^1*D$5*Inputs!$B$13)*(1+$A10)+Scenarios!$B$33*(1+$A10)^3*(1+D$5)^2*D$5*Inputs!$B$13)+Scenarios!$B$36*(1+Inputs!$C$35)^3*Inputs!$B$12))/5*Inputs!$C$36+Scenarios!E44)/Inputs!$B$6 | E10: =(((Inputs!$B$18)+(Inputs!$B$8+Inputs!$B$9)+((Scenarios!$B$34*(1+$A10)+Scenarios!$B$33*(1+$A10)^1*(1+E$5)^0*E$5*Inputs!$B$13)+Scenarios!$B$36*(1+Inputs!$C$35)^1*Inputs!$B$12)+(((Scenarios!$B$34*(1+$A10)+Scenarios!$B$33*(1+$A10)^1*(1+E$5)^0*E$5*Inputs!$B$13)*(1+$A10)+Scenarios!$B$33*(1+$A10)^2*(1+E$5)^1*E$5*Inputs!$B$13)+Scenarios!$B$36*(1+Inputs!$C$35)^2*Inputs!$B$12)+((((Scenarios!$B$34*(1+$A10)+Scenarios!$B$33*(1+$A10)^1*(1+E$5)^0*E$5*Inputs!$B$13)*(1+$A10)+Scenarios!$B$33*(1+$A10)^2*(1+E$5)^1*E$5*Inputs!$B$13)*(1+$A10)+Scenarios!$B$33*(1+$A10)^3*(1+E$5)^2*E$5*Inputs!$B$13)+Scenarios!$B$36*(1+Inputs!$C$35)^3*Inputs!$B$12))/5*Inputs!$C$36+Scenarios!E44)/Inputs!$B$6 | F10: =(((Inputs!$B$18)+(Inputs!$B$8+Inputs!$B$9)+((Scenarios!$B$34*(1+$A10)+Scenarios!$B$33*(1+$A10)^1*(1+F$5)^0*F$5*Inputs!$B$13)+Scenarios!$B$36*(1+Inputs!$C$35)^1*Inputs!$B$12)+(((Scenarios!$B$34*(1+$A10)+Scenarios!$B$33*(1+$A10)^1*(1+F$5)^0*F$5*Inputs!$B$13)*(1+$A10)+Scenarios!$B$33*(1+$A10)^2*(1+F$5)^1*F$5*Inputs!$B$13)+Scenarios!$B$36*(1+Inputs!$C$35)^2*Inputs!$B$12)+((((Scenarios!$B$34*(1+$A10)+Scenarios!$B$33*(1+$A10)^1*(1+F$5)^0*F$5*Inputs!$B$13)*(1+$A10)+Scenarios!$B$33*(1+$A10)^2*(1+F$5)^1*F$5*Inputs!$B$13)*(1+$A10)+Scenarios!$B$33*(1+$A10)^3*(1+F$5)^2*F$5*Inputs!$B$13)+Scenarios!$B$36*(1+Inputs!$C$35)^3*Inputs!$B$12))/5*Inputs!$C$36+Scenarios!E44)/Inputs!$B$6 | G10: =(((Inputs!$B$18)+(Inputs!$B$8+Inputs!$B$9)+((Scenarios!$B$34*(1+$A10)+Scenarios!$B$33*(1+$A10)^1*(1+G$5)^0*G$5*Inputs!$B$13)+Scenarios!$B$36*(1+Inputs!$C$35)^1*Inputs!$B$12)+(((Scenarios!$B$34*(1+$A10)+Scenarios!$B$33*(1+$A10)^1*(1+G$5)^0*G$5*Inputs!$B$13)*(1+$A10)+Scenarios!$B$33*(1+$A10)^2*(1+G$5)^1*G$5*Inputs!$B$13)+Scenarios!$B$36*(1+Inputs!$C$35)^2*Inputs!$B$12)+((((Scenarios!$B$34*(1+$A10)+Scenarios!$B$33*(1+$A10)^1*(1+G$5)^0*G$5*Inputs!$B$13)*(1+$A10)+Scenarios!$B$33*(1+$A10)^2*(1+G$5)^1*G$5*Inputs!$B$13)*(1+$A10)+Scenarios!$B$33*(1+$A10)^3*(1+G$5)^2*G$5*Inputs!$B$13)+Scenarios!$B$36*(1+Inputs!$C$35)^3*Inputs!$B$12))/5*Inputs!$C$36+Scenarios!E44)/Inputs!$B$6 | H10: =(((Inputs!$B$18)+(Inputs!$B$8+Inputs!$B$9)+((Scenarios!$B$34*(1+$A10)+Scenarios!$B$33*(1+$A10)^1*(1+H$5)^0*H$5*Inputs!$B$13)+Scenarios!$B$36*(1+Inputs!$C$35)^1*Inputs!$B$12)+(((Scenarios!$B$34*(1+$A10)+Scenarios!$B$33*(1+$A10)^1*(1+H$5)^0*H$5*Inputs!$B$13)*(1+$A10)+Scenarios!$B$33*(1+$A10)^2*(1+H$5)^1*H$5*Inputs!$B$13)+Scenarios!$B$36*(1+Inputs!$C$35)^2*Inputs!$B$12)+((((Scenarios!$B$34*(1+$A10)+Scenarios!$B$33*(1+$A10)^1*(1+H$5)^0*H$5*Inputs!$B$13)*(1+$A10)+Scenarios!$B$33*(1+$A10)^2*(1+H$5)^1*H$5*Inputs!$B$13)*(1+$A10)+Scenarios!$B$33*(1+$A10)^3*(1+H$5)^2*H$5*Inputs!$B$13)+Scenarios!$B$36*(1+Inputs!$C$35)^3*Inputs!$B$12))/5*Inputs!$C$36+Scenarios!E44)/Inputs!$B$6
A11: 0.2 | B11: =(((Inputs!$B$18)+(Inputs!$B$8+Inputs!$B$9)+((Scenarios!$B$34*(1+$A11)+Scenarios!$B$33*(1+$A11)^1*(1+B$5)^0*B$5*Inputs!$B$13)+Scenarios!$B$36*(1+Inputs!$C$35)^1*Inputs!$B$12)+(((Scenarios!$B$34*(1+$A11)+Scenarios!$B$33*(1+$A11)^1*(1+B$5)^0*B$5*Inputs!$B$13)*(1+$A11)+Scenarios!$B$33*(1+$A11)^2*(1+B$5)^1*B$5*Inputs!$B$13)+Scenarios!$B$36*(1+Inputs!$C$35)^2*Inputs!$B$12)+((((Scenarios!$B$34*(1+$A11)+Scenarios!$B$33*(1+$A11)^1*(1+B$5)^0*B$5*Inputs!$B$13)*(1+$A11)+Scenarios!$B$33*(1+$A11)^2*(1+B$5)^1*B$5*Inputs!$B$13)*(1+$A11)+Scenarios!$B$33*(1+$A11)^3*(1+B$5)^2*B$5*Inputs!$B$13)+Scenarios!$B$36*(1+Inputs!$C$35)^3*Inputs!$B$12))/5*Inputs!$C$36+Scenarios!E44)/Inputs!$B$6 | C11: =(((Inputs!$B$18)+(Inputs!$B$8+Inputs!$B$9)+((Scenarios!$B$34*(1+$A11)+Scenarios!$B$33*(1+$A11)^1*(1+C$5)^0*C$5*Inputs!$B$13)+Scenarios!$B$36*(1+Inputs!$C$35)^1*Inputs!$B$12)+(((Scenarios!$B$34*(1+$A11)+Scenarios!$B$33*(1+$A11)^1*(1+C$5)^0*C$5*Inputs!$B$13)*(1+$A11)+Scenarios!$B$33*(1+$A11)^2*(1+C$5)^1*C$5*Inputs!$B$13)+Scenarios!$B$36*(1+Inputs!$C$35)^2*Inputs!$B$12)+((((Scenarios!$B$34*(1+$A11)+Scenarios!$B$33*(1+$A11)^1*(1+C$5)^0*C$5*Inputs!$B$13)*(1+$A11)+Scenarios!$B$33*(1+$A11)^2*(1+C$5)^1*C$5*Inputs!$B$13)*(1+$A11)+Scenarios!$B$33*(1+$A11)^3*(1+C$5)^2*C$5*Inputs!$B$13)+Scenarios!$B$36*(1+Inputs!$C$35)^3*Inputs!$B$12))/5*Inputs!$C$36+Scenarios!E44)/Inputs!$B$6 | D11: =(((Inputs!$B$18)+(Inputs!$B$8+Inputs!$B$9)+((Scenarios!$B$34*(1+$A11)+Scenarios!$B$33*(1+$A11)^1*(1+D$5)^0*D$5*Inputs!$B$13)+Scenarios!$B$36*(1+Inputs!$C$35)^1*Inputs!$B$12)+(((Scenarios!$B$34*(1+$A11)+Scenarios!$B$33*(1+$A11)^1*(1+D$5)^0*D$5*Inputs!$B$13)*(1+$A11)+Scenarios!$B$33*(1+$A11)^2*(1+D$5)^1*D$5*Inputs!$B$13)+Scenarios!$B$36*(1+Inputs!$C$35)^2*Inputs!$B$12)+((((Scenarios!$B$34*(1+$A11)+Scenarios!$B$33*(1+$A11)^1*(1+D$5)^0*D$5*Inputs!$B$13)*(1+$A11)+Scenarios!$B$33*(1+$A11)^2*(1+D$5)^1*D$5*Inputs!$B$13)*(1+$A11)+Scenarios!$B$33*(1+$A11)^3*(1+D$5)^2*D$5*Inputs!$B$13)+Scenarios!$B$36*(1+Inputs!$C$35)^3*Inputs!$B$12))/5*Inputs!$C$36+Scenarios!E44)/Inputs!$B$6 | E11: =(((Inputs!$B$18)+(Inputs!$B$8+Inputs!$B$9)+((Scenarios!$B$34*(1+$A11)+Scenarios!$B$33*(1+$A11)^1*(1+E$5)^0*E$5*Inputs!$B$13)+Scenarios!$B$36*(1+Inputs!$C$35)^1*Inputs!$B$12)+(((Scenarios!$B$34*(1+$A11)+Scenarios!$B$33*(1+$A11)^1*(1+E$5)^0*E$5*Inputs!$B$13)*(1+$A11)+Scenarios!$B$33*(1+$A11)^2*(1+E$5)^1*E$5*Inputs!$B$13)+Scenarios!$B$36*(1+Inputs!$C$35)^2*Inputs!$B$12)+((((Scenarios!$B$34*(1+$A11)+Scenarios!$B$33*(1+$A11)^1*(1+E$5)^0*E$5*Inputs!$B$13)*(1+$A11)+Scenarios!$B$33*(1+$A11)^2*(1+E$5)^1*E$5*Inputs!$B$13)*(1+$A11)+Scenarios!$B$33*(1+$A11)^3*(1+E$5)^2*E$5*Inputs!$B$13)+Scenarios!$B$36*(1+Inputs!$C$35)^3*Inputs!$B$12))/5*Inputs!$C$36+Scenarios!E44)/Inputs!$B$6 | F11: =(((Inputs!$B$18)+(Inputs!$B$8+Inputs!$B$9)+((Scenarios!$B$34*(1+$A11)+Scenarios!$B$33*(1+$A11)^1*(1+F$5)^0*F$5*Inputs!$B$13)+Scenarios!$B$36*(1+Inputs!$C$35)^1*Inputs!$B$12)+(((Scenarios!$B$34*(1+$A11)+Scenarios!$B$33*(1+$A11)^1*(1+F$5)^0*F$5*Inputs!$B$13)*(1+$A11)+Scenarios!$B$33*(1+$A11)^2*(1+F$5)^1*F$5*Inputs!$B$13)+Scenarios!$B$36*(1+Inputs!$C$35)^2*Inputs!$B$12)+((((Scenarios!$B$34*(1+$A11)+Scenarios!$B$33*(1+$A11)^1*(1+F$5)^0*F$5*Inputs!$B$13)*(1+$A11)+Scenarios!$B$33*(1+$A11)^2*(1+F$5)^1*F$5*Inputs!$B$13)*(1+$A11)+Scenarios!$B$33*(1+$A11)^3*(1+F$5)^2*F$5*Inputs!$B$13)+Scenarios!$B$36*(1+Inputs!$C$35)^3*Inputs!$B$12))/5*Inputs!$C$36+Scenarios!E44)/Inputs!$B$6 | G11: =(((Inputs!$B$18)+(Inputs!$B$8+Inputs!$B$9)+((Scenarios!$B$34*(1+$A11)+Scenarios!$B$33*(1+$A11)^1*(1+G$5)^0*G$5*Inputs!$B$13)+Scenarios!$B$36*(1+Inputs!$C$35)^1*Inputs!$B$12)+(((Scenarios!$B$34*(1+$A11)+Scenarios!$B$33*(1+$A11)^1*(1+G$5)^0*G$5*Inputs!$B$13)*(1+$A11)+Scenarios!$B$33*(1+$A11)^2*(1+G$5)^1*G$5*Inputs!$B$13)+Scenarios!$B$36*(1+Inputs!$C$35)^2*Inputs!$B$12)+((((Scenarios!$B$34*(1+$A11)+Scenarios!$B$33*(1+$A11)^1*(1+G$5)^0*G$5*Inputs!$B$13)*(1+$A11)+Scenarios!$B$33*(1+$A11)^2*(1+G$5)^1*G$5*Inputs!$B$13)*(1+$A11)+Scenarios!$B$33*(1+$A11)^3*(1+G$5)^2*G$5*Inputs!$B$13)+Scenarios!$B$36*(1+Inputs!$C$35)^3*Inputs!$B$12))/5*Inputs!$C$36+Scenarios!E44)/Inputs!$B$6 | H11: =(((Inputs!$B$18)+(Inputs!$B$8+Inputs!$B$9)+((Scenarios!$B$34*(1+$A11)+Scenarios!$B$33*(1+$A11)^1*(1+H$5)^0*H$5*Inputs!$B$13)+Scenarios!$B$36*(1+Inputs!$C$35)^1*Inputs!$B$12)+(((Scenarios!$B$34*(1+$A11)+Scenarios!$B$33*(1+$A11)^1*(1+H$5)^0*H$5*Inputs!$B$13)*(1+$A11)+Scenarios!$B$33*(1+$A11)^2*(1+H$5)^1*H$5*Inputs!$B$13)+Scenarios!$B$36*(1+Inputs!$C$35)^2*Inputs!$B$12)+((((Scenarios!$B$34*(1+$A11)+Scenarios!$B$33*(1+$A11)^1*(1+H$5)^0*H$5*Inputs!$B$13)*(1+$A11)+Scenarios!$B$33*(1+$A11)^2*(1+H$5)^1*H$5*Inputs!$B$13)*(1+$A11)+Scenarios!$B$33*(1+$A11)^3*(1+H$5)^2*H$5*Inputs!$B$13)+Scenarios!$B$36*(1+Inputs!$C$35)^3*Inputs!$B$12))/5*Inputs!$C$36+Scenarios!E44)/Inputs!$B$6
A13: Net cash held at the Base-case Mar-2030 level in grid 1 (second-order effect). Current price for reference: | H13: =Inputs!$B$5
A15: Value per share at exit (JPY): rows = exit EV / 5-yr-mean EBITDA, columns = 5-yr mean EBITDA (JPY bn)
A16: mult \ EBITDA | B16: 450 | C16: 500 | D16: 550 | E16: 600 | F16: 650 | G16: 700 | H16: 800
A17: 8 | B17: =($A17*B$16*1000+Scenarios!E44)/Inputs!$B$6 | C17: =($A17*C$16*1000+Scenarios!E44)/Inputs!$B$6 | D17: =($A17*D$16*1000+Scenarios!E44)/Inputs!$B$6 | E17: =($A17*E$16*1000+Scenarios!E44)/Inputs!$B$6 | F17: =($A17*F$16*1000+Scenarios!E44)/Inputs!$B$6 | G17: =($A17*G$16*1000+Scenarios!E44)/Inputs!$B$6 | H17: =($A17*H$16*1000+Scenarios!E44)/Inputs!$B$6
A18: 10.4 | B18: =($A18*B$16*1000+Scenarios!E44)/Inputs!$B$6 | C18: =($A18*C$16*1000+Scenarios!E44)/Inputs!$B$6 | D18: =($A18*D$16*1000+Scenarios!E44)/Inputs!$B$6 | E18: =($A18*E$16*1000+Scenarios!E44)/Inputs!$B$6 | F18: =($A18*F$16*1000+Scenarios!E44)/Inputs!$B$6 | G18: =($A18*G$16*1000+Scenarios!E44)/Inputs!$B$6 | H18: =($A18*H$16*1000+Scenarios!E44)/Inputs!$B$6
A19: 11.6 | B19: =($A19*B$16*1000+Scenarios!E44)/Inputs!$B$6 | C19: =($A19*C$16*1000+Scenarios!E44)/Inputs!$B$6 | D19: =($A19*D$16*1000+Scenarios!E44)/Inputs!$B$6 | E19: =($A19*E$16*1000+Scenarios!E44)/Inputs!$B$6 | F19: =($A19*F$16*1000+Scenarios!E44)/Inputs!$B$6 | G19: =($A19*G$16*1000+Scenarios!E44)/Inputs!$B$6 | H19: =($A19*H$16*1000+Scenarios!E44)/Inputs!$B$6
A20: 13.5 | B20: =($A20*B$16*1000+Scenarios!E44)/Inputs!$B$6 | C20: =($A20*C$16*1000+Scenarios!E44)/Inputs!$B$6 | D20: =($A20*D$16*1000+Scenarios!E44)/Inputs!$B$6 | E20: =($A20*E$16*1000+Scenarios!E44)/Inputs!$B$6 | F20: =($A20*F$16*1000+Scenarios!E44)/Inputs!$B$6 | G20: =($A20*G$16*1000+Scenarios!E44)/Inputs!$B$6 | H20: =($A20*H$16*1000+Scenarios!E44)/Inputs!$B$6
A21: 16 | B21: =($A21*B$16*1000+Scenarios!E44)/Inputs!$B$6 | C21: =($A21*C$16*1000+Scenarios!E44)/Inputs!$B$6 | D21: =($A21*D$16*1000+Scenarios!E44)/Inputs!$B$6 | E21: =($A21*E$16*1000+Scenarios!E44)/Inputs!$B$6 | F21: =($A21*F$16*1000+Scenarios!E44)/Inputs!$B$6 | G21: =($A21*G$16*1000+Scenarios!E44)/Inputs!$B$6 | H21: =($A21*H$16*1000+Scenarios!E44)/Inputs!$B$6
A22: 20 | B22: =($A22*B$16*1000+Scenarios!E44)/Inputs!$B$6 | C22: =($A22*C$16*1000+Scenarios!E44)/Inputs!$B$6 | D22: =($A22*D$16*1000+Scenarios!E44)/Inputs!$B$6 | E22: =($A22*E$16*1000+Scenarios!E44)/Inputs!$B$6 | F22: =($A22*F$16*1000+Scenarios!E44)/Inputs!$B$6 | G22: =($A22*G$16*1000+Scenarios!E44)/Inputs!$B$6 | H22: =($A22*H$16*1000+Scenarios!E44)/Inputs!$B$6
A23: 25 | B23: =($A23*B$16*1000+Scenarios!E44)/Inputs!$B$6 | C23: =($A23*C$16*1000+Scenarios!E44)/Inputs!$B$6 | D23: =($A23*D$16*1000+Scenarios!E44)/Inputs!$B$6 | E23: =($A23*E$16*1000+Scenarios!E44)/Inputs!$B$6 | F23: =($A23*F$16*1000+Scenarios!E44)/Inputs!$B$6 | G23: =($A23*G$16*1000+Scenarios!E44)/Inputs!$B$6 | H23: =($A23*H$16*1000+Scenarios!E44)/Inputs!$B$6
A24: 30 | B24: =($A24*B$16*1000+Scenarios!E44)/Inputs!$B$6 | C24: =($A24*C$16*1000+Scenarios!E44)/Inputs!$B$6 | D24: =($A24*D$16*1000+Scenarios!E44)/Inputs!$B$6 | E24: =($A24*E$16*1000+Scenarios!E44)/Inputs!$B$6 | F24: =($A24*F$16*1000+Scenarios!E44)/Inputs!$B$6 | G24: =($A24*G$16*1000+Scenarios!E44)/Inputs!$B$6 | H24: =($A24*H$16*1000+Scenarios!E44)/Inputs!$B$6

Sheet Sources
A1: Sources
A2: Tags: F = company primary document / exchange data; A = attributed or assumption; E = our arithmetic.
A4: Item | B4: Source | C4: URL | D4: Tag
A5: History FY3/12-FY3/22 | B5: Murata Fact Book 2022 | C5: https://corporate.murata.com/-/media/corporate/about/newsroom/news/irnews/irnews/2022/0713/factbook2022.ashx | D5: F
A6: History FY3/16-FY3/26 | B6: Murata Fact Book 2026 | C6: https://corporate.murata.com/-/media/corporate/about/newsroom/news/irnews/irnews/2026/0626/factbook2026.ashx | D6: F
A7: FY3/27 guidance (31 Jul 2026) | B7: Murata 1Q FY2026 results | C7: https://corporate.murata.com/-/media/corporate/about/newsroom/news/irnews/irnews/2026/0731d/26q1-e-speach.ashx | D7: F
A8: Monthly prices | B8: Yahoo Finance chart API | C8: https://query1.finance.yahoo.com/v8/finance/chart/6981.T | D8: F
A9: Consensus TP ¥10,414, fwd P/E 37.8x | B9: stockanalysis.com, 2-Oct-2026 | C9: https://stockanalysis.com/quote/tyo/6981/ | D9: A
A10: Valuation method ruling | B10: Roy, 2-Oct-2026: EV / mid-cycle EBITDA band (memory card D-M1 logic) | D10: A
A11: Scenario drivers | B11: targets/MLCC/research memos 01-03, 06 | D11: A/E
